Workbook
Name MODEL_NO: Sheet2!$C$38:$C$43

Sheet Mini 2 200
A1: Technical Data Sheet - Domestic Thermodynamics Solar Heat Pump
A44: WORLDS MOST ADVANCED SOLAR HEAT PUMP TECHNOLOGY
A53: NEXT-GEN THERMODYNAMICS SOLAR HEAT PUMP
A55: Technical Data Sheet - Domestic Thermodynamics Solar Heat Pump
A59: NEXT-GEN THERMODYNAMICS SOLAR HEAT PUMP | E59: The Thermodynamic Solar System joins two incomplete technologies, the heat pump and the solar thermal collector. Heat pumps are quite efficient equipment but the heat they produce from their renewable component varies only according to changes in the temperature of the environment. Thermal solar collectors are the best source of heat on hot and sunny days, but they are totally inefficient whenever there is no sun. The thermodynamic Solar Technology manages to surpass the limitations of both the heat pump and solar collector. Through the cooling liquid (R134a or R407c ) which covers a closed circuit, the liquid goes into the solar panel and extract the thermal energy of sun , rain, wind, environment temperature and other climate factors . During this process the liquid gains heat in a more favorable way than a heat pump. after this stage , the heat it transferred to an exchanger with the help of a small compressor, which heats the water , The liquid cools down and the circuit is repeated. As the fluid has a boiling temperature of approximately -30C , the system works even when there is no sun and it even works at night, hail, rain, wind or shine , unlike the traditional solar thermal system. The energy consumption of the system is basically the same as fridge compressor that makes the liquid circulate. there are no ventilators that help the evaporation process, of defrost cycles, which imply unnecessary energy consumption, unlike what happened with heat pump
A82: The Thermodynamic Solar technology offers high performance even at night, with rain, or on overcast days, this being an advantage over conventional solar panels whose performance is limited as they rely exclusively on direct solar radiation and a compulsory southward orientation (Northern Hemisphere).
A91: NEXT-GEN THERMODYNAMICS SOLAR PANEL COLLECTOR Latest generation thermodynamic solar collector: it is a roll-bond panel with double channel through which the fluid refrigerant circulates, being able of providing high performance at night and in adverse climate conditions. Life span of more than 10 years: the panel is made of anodized aluminum 30 micron, which ensures The following properties • Great toughness at high and low temperatures. • High surface hardness. • Resistance to abrasion and weakening. • High protection against dust and dampness. • Corrosion-resistant. User-friendly transport and easy handling systems: small size 2 m x 0,8 m. Versatility: easy integration on facades, roofs or any other surface. It is not necessary to reinforce structures as it is a lightweight panel, 8 kg. Optimized solar catchment area: both sides of the panel, 3,20 sqm. No need to be south orientated (Northern Hemisphere). Vindsol recommends to orientate the collector as much as possible to the sun and exposed to the elements, such as wind and rain. Regular maintenance is not necessary.
A107: NEXT-GEN THERMODYNAMICS SOLAR HEAT PUMP
A109: TECHNICAL SPECIFICATION
A110: Model | C110: MiNi2-300
A112: Thermodynamic Solar Panel
A113: Material & Finish | C113: Powder coated Anodised aluminium Alloy panel
A114: Thickness | B114: L X W X T (mm) | C114: 2 mm aluminium for increased mechanical strength
A115: Protection | C115: Corrosion resistant and adaptability to all weathers
A116: Dimensions L X W X T | B116: mm | C116: 2000 X 800 * 20
A117: Maximum working Pr. | B117: Bar | C117: 10
A118: Test pressure | B118: Bar | C118: 15
A119: Maximum exposure temp. | B119: °C | C119: 100
A120: Minimum running temp. | B120: °C | C120: 10
A121: Qty | B121: Nos | C121: =VLOOKUP(C110,Sheet2!A47:AF52,10) -> 2
A122: Thermodynamic Box
A123: Absorbed power KW (Average/Max) | C123: 0.72 KW
A124: Thermal Calorific power (Average/Max) | C124: 3.6 KW
A125: Compressor Type | C125: Rotary Type - Heat pump COmpressor
A126: Throttle Type | C126: Electronic expansion valve (EEV)
A127: Rated outlet water temp.℃ | C127: 50-55 Deg
A128: Max outlet water temp.℃ | C128: 55 Deg
A129: Power V/Ph/Hz | C129: 220V/1PH/ 50Hz
A130: Heat exchanger type | C130: High efficiency tube in tube heat exchanger
A131: Heat exchanger No. | C131: 1
A132: Controller type | C132: Intelligent PCB & LCD
A133: Ambient Temperature | C133: (0℃~+45 ℃)
A134: Low pressure protection | C134: Yes
A135: High pressure protection | C135: Yes
A136: Automatic defroting system | C136: Yes
A137: Overload protection | C137: Yes
A138: Noise in 1 meter | C138: 50 dB
A139: Water pipe size | C139: 25 NB
A140: Water flow volume | C140: 2 M3/hr
A141: Circulation Pump | C141: Additional
...

Sheet Mini 2 300
A1: Technical Data Sheet - Domestic Thermodynamics Solar Heat Pump
A53: NEXT-GEN THERMODYNAMICS SOLAR HEAT PUMP
A55: Technical Data Sheet - Domestic Thermodynamics Solar Heat Pump
A59: NEXT-GEN THERMODYNAMICS SOLAR HEAT PUMP | E59: The Thermodynamic Solar System joins two incomplete technologies, the heat pump and the solar thermal collector. Heat pumps are quite efficient equipment but the heat they produce from their renewable component varies only according to changes in the temperature of the environment. Thermal solar collectors are the best source of heat on hot and sunny days, but they are totally inefficient whenever there is no sun. The thermodynamic Solar Technology manages to surpass the limitations of both the heat pump and solar collector. Through the cooling liquid (R134a or R407c ) which covers a closed circuit, the liquid goes into the solar panel and extract the thermal energy of sun , rain, wind, environment temperature and other climate factors . During this process the liquid gains heat in a more favorable way than a heat pump. after this stage , the heat it transferred to an exchanger with the help of a small compressor, which heats the water , The liquid cools down and the circuit is repeated. As the fluid has a boiling temperature of approximately -30C , the system works even when there is no sun and it even works at night, hail, rain, wind or shine , unlike the traditional solar thermal system. The energy consumption of the system is basically the same as fridge compressor that makes the liquid circulate. there are no ventilators that help the evaporation process, of defrost cycles, which imply unnecessary energy consumption, unlike what happened with heat pump
A82: The Thermodynamic Solar technology offers high performance even at night, with rain, or on overcast days, this being an advantage over conventional solar panels whose performance is limited as they rely exclusively on direct solar radiation and a compulsory southward orientation (Northern Hemisphere).
A91: NEXT-GEN THERMODYNAMICS SOLAR PANEL COLLECTOR Latest generation thermodynamic solar collector: it is a roll-bond panel with double channel through which the fluid refrigerant circulates, being able of providing high performance at night and in adverse climate conditions. Life span of more than 10 years: the panel is made of anodized aluminum 30 micron, which ensures The following properties • Great toughness at high and low temperatures. • High surface hardness. • Resistance to abrasion and weakening. • High protection against dust and dampness. • Corrosion-resistant. User-friendly transport and easy handling systems: small size 2 m x 0,8 m. Versatility: easy integration on facades, roofs or any other surface. It is not necessary to reinforce structures as it is a lightweight panel, 8 kg. Optimized solar catchment area: both sides of the panel, 3,20 sqm. No need to be south orientated (Northern Hemisphere). Vindsol recommends to orientate the collector as much as possible to the sun and exposed to the elements, such as wind and rain. Regular maintenance is not necessary.
A107: NEXT-GEN THERMODYNAMICS SOLAR HEAT PUMP
A109: TECHNICAL SPECIFICATION
A110: Model | C110: MiNi2-300
A112: Thermodynamic Solar Panel
A113: Material & Finish | C113: Powder coated Anodised aluminium Alloy panel
A114: Thickness | B114: L X W X T (mm) | C114: 2 mm aluminium for increased mechanical strength
A115: Protection | C115: Corrosion resistant and adaptability to all weathers
A116: Dimensions L X W X T | B116: mm | C116: 2000 X 800 * 20
A117: Maximum working Pr. | B117: Bar | C117: 10
A118: Test pressure | B118: Bar | C118: 15
A119: Maximum exposure temp. | B119: °C | C119: 100
A120: Minimum running temp. | B120: °C | C120: 10
A121: Qty | B121: Nos | C121: =VLOOKUP(C110,Sheet2!A47:AF52,10) -> 2
A122: Thermodynamic Box
A123: Absorbed power KW (Average/Max) | C123: 0.72 KW
A124: Thermal Calorific power (Average/Max) | C124: 3.6 KW
A125: Compressor Type | C125: Rotary Type - Heat pump COmpressor
A126: Throttle Type | C126: Electronic expansion valve (EEV)
A127: Rated outlet water temp.℃ | C127: 50-55 Deg
A128: Max outlet water temp.℃ | C128: 55 Deg
A129: Power V/Ph/Hz | C129: 220V/1PH/ 50Hz
A130: Heat exchanger type | C130: High efficiency tube in tube heat exchanger
A131: Heat exchanger No. | C131: 1
A132: Controller type | C132: Intelligent PCB & LCD
A133: Ambient Temperature | C133: (0℃~+45 ℃)
A134: Low pressure protection | C134: Yes
A135: High pressure protection | C135: Yes
A136: Automatic defroting system | C136: Yes
A137: Overload protection | C137: Yes
A138: Noise in 1 meter | C138: 50 dB
A139: Water pipe size | C139: 25 NB
A140: Water flow volume | C140: 2 M3/hr
A141: Circulation Pump | C141: Additional
A142: Net Weight | B142: Kg | C142: 50 Kg Apprx
...

Sheet Mini 4 500
A1: Technical Data Sheet - Domestic Thermodynamics Solar Heat Pump
A53: NEXT-GEN THERMODYNAMICS SOLAR HEAT PUMP
A55: Technical Data Sheet - Domestic Thermodynamics Solar Heat Pump
A59: NEXT-GEN THERMODYNAMICS SOLAR HEAT PUMP | E59: The Thermodynamic Solar System joins two incomplete technologies, the heat pump and the solar thermal collector. Heat pumps are quite efficient equipment but the heat they produce from their renewable component varies only according to changes in the temperature of the environment. Thermal solar collectors are the best source of heat on hot and sunny days, but they are totally inefficient whenever there is no sun. The thermodynamic Solar Technology manages to surpass the limitations of both the heat pump and solar collector. Through the cooling liquid (R134a or R407c ) which covers a closed circuit, the liquid goes into the solar panel and extract the thermal energy of sun , rain, wind, environment temperature and other climate factors . During this process the liquid gains heat in a more favorable way than a heat pump. after this stage , the heat it transferred to an exchanger with the help of a small compressor, which heats the water , The liquid cools down and the circuit is repeated. As the fluid has a boiling temperature of approximately -30C , the system works even when there is no sun and it even works at night, hail, rain, wind or shine , unlike the traditional solar thermal system. The energy consumption of the system is basically the same as fridge compressor that makes the liquid circulate. there are no ventilators that help the evaporation process, of defrost cycles, which imply unnecessary energy consumption, unlike what happened with heat pump
A82: The Thermodynamic Solar technology offers high performance even at night, with rain, or on overcast days, this being an advantage over conventional solar panels whose performance is limited as they rely exclusively on direct solar radiation and a compulsory southward orientation (Northern Hemisphere).
A91: NEXT-GEN THERMODYNAMICS SOLAR PANEL COLLECTOR Latest generation thermodynamic solar collector: it is a roll-bond panel with double channel through which the fluid refrigerant circulates, being able of providing high performance at night and in adverse climate conditions. Life span of more than 10 years: the panel is made of anodized aluminum 30 micron, which ensures The following properties • Great toughness at high and low temperatures. • High surface hardness. • Resistance to abrasion and weakening. • High protection against dust and dampness. • Corrosion-resistant. User-friendly transport and easy handling systems: small size 2 m x 0,8 m. Versatility: easy integration on facades, roofs or any other surface. It is not necessary to reinforce structures as it is a lightweight panel, 8 kg. Optimized solar catchment area: both sides of the panel, 3,20 sqm. No need to be south orientated (Northern Hemisphere). Vindsol recommends to orientate the collector as much as possible to the sun and exposed to the elements, such as wind and rain. Regular maintenance is not necessary.
A107: NEXT-GEN THERMODYNAMICS SOLAR HEAT PUMP
A109: TECHNICAL SPECIFICATION
A110: Model | C110: MiNi4-500
A112: Thermodynamic Solar Panel
A113: Material & Finish | C113: Powder coated Anodised aluminium Alloy panel
A114: Thickness | B114: L X W X T (mm) | C114: 2 mm aluminium for increased mechanical strength
A115: Protection | C115: Corrosion resistant and adaptability to all weathers
A116: Dimensions L X W X T | B116: mm | C116: 2000 X 800 * 20
A117: Maximum working Pr. | B117: Bar | C117: 10
A118: Test pressure | B118: Bar | C118: 15
A119: Maximum exposure temp. | B119: °C | C119: 100
A120: Minimum running temp. | B120: °C | C120: 10
A121: Qty | B121: Nos | C121: 8
A122: Thermodynamic Box
A123: Absorbed power KW (Average/Max) | C123: 0.9/1.78 KW
A124: Thermal Calorific power (Average/Max) | C124: 3.55/7.16 KW
A125: Compressor Type | C125: Rotary Type - Heat pump COmpressor
A126: Throttle Type | C126: Electronic expansion valve (EEV)
A127: Rated outlet water temp.℃ | C127: 50-55 Deg
A128: Max outlet water temp.℃ | C128: 55 Deg
A129: Power V/Ph/Hz | C129: 220V/1PH/ 50Hz
A130: Heat exchanger type | C130: High efficiency tube in tube heat exchanger
A131: Heat exchanger No. | C131: 1
A132: Controller type | C132: Intelligent PCB & LCD
A133: Ambient Temperature | C133: (0℃~+45 ℃)
A134: Low pressure protection | C134: Yes
A135: High pressure protection | C135: Yes
A136: Automatic defroting system | C136: Yes
A137: Overload protection | C137: Yes
A138: Noise in 1 meter | C138: 50 dB
A139: Water pipe size | C139: 25 NB
A140: Water flow volume | C140: 2 M3/hr
A141: Circulation Pump | C141: Additional
A142: Net Weight | B142: Kg | C142: 50 Kg Apprx
...

Sheet Sheet1
A7: S.No | B7: Decsription | C7: Unit | D7: Qty
A8: 1 | B8: Thermodybamic Solar panel 2 NO s | C8: No | D8: 1
B9: In plywood o rwooden case
B10: 2200 X 100 X 1200 mm Box APPRX, 50 Kg
A17: 2 | B17: Thermodynamic BOX with accessories Packed in wooden case , Apppx Dimesnion : 800 X 500 X 600 , Appx 75 Kg | C17: No | D17: 1
A27: 3 | B27: GLASS Lined Hot water Storage Tank , 300 Lts , 0.82 CBM , Apprx 100 Kg with xtra wooden Packing | C27: No | D27: 1

Sheet QTN
A1: Techno - Commercial Data Sheet - Domestic Thermodynamics Solar Heat Pump
A53: NEXT-GEN THERMODYNAMICS SOLAR HEAT PUMP
A55: Technical Data Sheet - Domestic Thermodynamics Solar Heat Pump
A59: NEXT-GEN THERMODYNAMICS SOLAR HEAT PUMP | E59: The Thermodynamic Solar System joins two incomplete technologies, the heat pump and the solar thermal collector. Heat pumps are quite efficient equipment but the heat they produce from their renewable component varies only according to changes in the temperature of the environment. Thermal solar collectors are the best source of heat on hot and sunny days, but they are totally inefficient whenever there is no sun. The thermodynamic Solar Technology manages to surpass the limitations of both the heat pump and solar collector. Through the cooling liquid (R134a or R407c ) which covers a closed circuit, the liquid goes into the solar panel and extract the thermal energy of sun , rain, wind, environment temperature and other climate factors . During this process the liquid gains heat in a more favorable way than a heat pump. after this stage , the heat it transferred to an exchanger with the help of a small compressor, which heats the water , The liquid cools down and the circuit is repeated. As the fluid has a boiling temperature of approximately -30C , the system works even when there is no sun and it even works at night, hail, rain, wind or shine , unlike the traditional solar thermal system. The energy consumption of the system is basically the same as fridge compressor that makes the liquid circulate. there are no ventilators that help the evaporation process, of defrost cycles, which imply unnecessary energy consumption, unlike what happened with heat pump
A82: The Thermodynamic Solar technology offers high performance even at night, with rain, or on overcast days, this being an advantage over conventional solar panels whose performance is limited as they rely exclusively on direct solar radiation and a compulsory southward orientation (Northern Hemisphere).
A90: NEXT-GEN THERMODYNAMICS SOLAR PANEL COLLECTOR Latest generation thermodynamic solar collector: it is a roll-bond panel with double channel through which the fluid refrigerant circulates, being able of providing high performance at night and in adverse climate conditions. Life span of more than 10 years: the panel is made of anodized aluminum 30 micron, which ensures The following properties • Great toughness at high and low temperatures. • High surface hardness. • Resistance to abrasion and weakening. • High protection against dust and dampness. • Corrosion-resistant. User-friendly transport and easy handling systems: small size 2 m x 0,8 m. Versatility: easy integration on facades, roofs or any other surface. It is not necessary to reinforce structures as it is a lightweight panel, 8 kg. Optimized solar catchment area: both sides of the panel, 3,20 sqm. No need to be south orientated (Northern Hemisphere). Vindsol recommends to orientate the collector as much as possible to the sun and exposed to the elements, such as wind and rain. Regular maintenance is not necessary.
A107: NEXT-GEN THERMODYNAMICS SOLAR HEAT PUMP
A109: TECHNICAL SPECIFICATION
A110: Model | C110: VTDHP 24MAX3000
A112: Thermodynamic Solar Panel
A113: Material & Finish | C113: Powder coated Anodised aluminium Alloy panel
A114: Thickness | B114: L X W X T (mm) | C114: 2 mm aluminium for increased mechanical strength
A115: Protection | C115: Corrosion resistant and adaptability to all weathers
A116: Dimensions L X W X T | B116: mm | C116: 2000 X 800 * 20
A117: Maximum working Pr. | B117: Bar | C117: 10
A118: Test pressure | B118: Bar | C118: 15
A119: Maximum exposure temp. | B119: °C | C119: 100
A120: Minimum running temp. | B120: °C | C120: 10
A121: Qty | B121: Nos | C121: 24
A122: Exposed collecting surface | B122: m2 | C122: 38.4
A123: Thermodynamic Box
A124: Absorbed power KW (Average/Max) | C124: 4.2/6.25 KW
A125: Thermal Calorific power (Average/Max) | C125: 16 / 28 KW
A126: Compressor Type | C126: Scroll - Copeland Emerson
A127: Throttle Type | C127: Electronic expansion valve (EEV)
A128: Rated outlet water temp.℃ | C128: 55 Deg
A129: Max outlet water temp.℃ | C129: 55 Deg
A130: Power V/Ph/Hz | C130: 380 ～415V/3PH/ 50Hz
A131: Heat exchanger type | C131: High efficiency tube in tube heat exchanger
A132: Heat exchanger No. | C132: 1
A133: Controller type | C133: Intelligent PCB & LCD
A134: Ambient Temperature | C134: (0℃~+45 ℃)
A135: Low pressure protection | C135: Yes
A136: High pressure protection | C136: Yes
A137: Automatic defroting system | C137: Yes
A138: Overload protection | C138: Yes
A139: Noise in 1 meter | C139: 50 dB
A140: Water pipe size | C140: 25 NB
A141: Water flow volume | C141: 4 M3/hr
A142: Circulation Pump | C142: Additional
...

Sheet Sheet2
A1: Model | B1: MiNi1-200 | C1: MiNi1-300 | D1: MiNi2-300 | E1: MiNi2-500 | F1: MiNi4-500
A2: Material & Finish | B2: Powder coated Anodised aluminium Alloy panel | C2: Powder coated Anodised aluminium Alloy panel | D2: Powder coated Anodised aluminium Alloy panel | E2: Powder coated Anodised aluminium Alloy panel | F2: Powder coated Anodised aluminium Alloy panel
A3: Thickness | B3: 2mm aluminium for increased mechanical strength | C3: 2mm aluminium for increased mechanical strength | D3: 2mm aluminium for increased mechanical strength | E3: 2mm aluminium for increased mechanical strength | F3: 2mm aluminium for increased mechanical strength
A4: Protection | B4: Corrosion resistant and adaptability to all weathers | C4: Corrosion resistant and adaptability to all weathers | D4: Corrosion resistant and adaptability to all weathers | E4: Corrosion resistant and adaptability to all weathers | F4: Corrosion resistant and adaptability to all weathers
A5: Dimensions L X W X T | B5: 2000 X 800 * 20 | C5: 2000 X 800 * 20 | D5: 2000 X 800 * 20 | E5: 2000 X 800 * 20 | F5: 2000 X 800 * 20
A6: Maximum working Pr. | B6: 10 | C6: 10 | D6: 10 | E6: 10 | F6: 10
A7: Test pressure | B7: 15 | C7: 15 | D7: 15 | E7: 15 | F7: 15
A8: Maximum exposure temp. | B8: 100 | C8: 100 | D8: 100 | E8: 100 | F8: 100
A9: Minimum running temp. | B9: 10 | C9: 10 | D9: 10 | E9: 10 | F9: 10
A10: Qty | B10: 1 | C10: 1 | D10: 2 | E10: 2 | F10: 4
A11: Absorbed power (Average/Max) | B11: 650 | C11: 890 | D11: 890 | E11: 890 | F11: 890
A12: Thermal power (Average/Max) | B12: 3490 | C12: 4750 | D12: 4750 | E12: 4750 | F12: 4750
A13: Electrical support power | B13: 1500 | C13: 1500 | D13: 1500 | E13: 1500 | F13: 1500
A14: Compressor Type | B14: Rotary | C14: Rotary | D14: Rotary | E14: Rotary | F14: Rotary
A15: Compressor Noise Level | B15: 45 | C15: 45 | D15: 45 | E15: 45 | F15: 45
A16: Circulation Pump | B16: Builtin Hot water circualtor Pump | C16: Builtin Hot water circualtor Pump | D16: Builtin Hot water circualtor Pump | E16: Builtin Hot water circualtor Pump | F16: Builtin Hot water circualtor Pump
A17: Net Weight
A18: Cabinet | B18: Stainless Steel / Galvanised Steek | C18: Stainless Steel / Galvanised Steek | D18: Stainless Steel / Galvanised Steek | E18: Stainless Steel / Galvanised Steek | F18: Stainless Steel / Galvanised Steek
A19: Dimension | B19: 500 X 450 X 375 | C19: 500 X 450 X 375 | D19: 500 X 450 X 375 | E19: 500 X 450 X 375 | F19: 500 X 450 X 375
A20: Cooling Fluid * | B20: R134a | C20: R134a | D20: R134a | E20: R134a | F20: R134a
A21: Piping Material | B21: Copper (DHP ISO1337) | C21: Copper (DHP ISO1337) | D21: Copper (DHP ISO1337) | E21: Copper (DHP ISO1337) | F21: Copper (DHP ISO1337)
A22: Line of liquid | B22: 1/4” | C22: 1/4” | D22: 3/8" | E22: 3/8" | F22: 3/8"
A23: Line of aspiration | B23: 3/8” | C23: 3/8” | D23: 1/2" | E23: 1/2" | F23: 1/2"
A24: Volume | B24: 200 | C24: 300 | D24: 300 | E24: 500 | F24: 500
A25: Type of internal Tank | B25: MS with SPL EPOXY enamel Coated | C25: MS with SPL EPOXY enamel Coated | D25: MS with SPL EPOXY enamel Coated | E25: MS with SPL EPOXY enamel Coated | F25: MS with SPL EPOXY enamel Coated
A26: Hydraulic joints | B26: 3/4” Male | 3/4” Male 1/2 Female | 3/4” Female | C26: 3/4” Male | 3/4” Male 1/2 Female | 3/4” Female | D26: 3/4” Male | 3/4” Male 1/2 Female | 3/4” Female | E26: 3/4” Male | 3/4” Male 1/2 Female | 3/4” Female | F26: 3/4” Male | 3/4” Male 1/2 Female | 3/4” Female
A27: Maximum pressure | B27: 7 | C27: 7 | D27: 7 | E27: 7 | F27: 7
A28: Test pressure | B28: 10 | C28: 10 | D28: 10 | E28: 10 | F28: 10
A29: Maximum water temp. | B29: 60 | C29: 60 | D29: 60 | E29: 60 | F29: 60
A30: Water temperature | B30: 55 | C30: 55 | D30: 55 | E30: 55 | F30: 55
A31: Power feed | B31: 230 Single Phase / 50 | C31: 230 Single Phase / 50 | D31: 230 Single Phase / 50 | E31: 230 Single Phase / 50 | F31: 230 Single Phase / 50
A32: Controller | B32: Next Gen PCB controller | C32: Next Gen PCB controller | D32: Next Gen PCB controller | E32: Next Gen PCB controller | F32: Next Gen PCB controller
C37: MODEL_NO
C38: MiNi1-200
C39: MiNi1-300
C40: MiNi2-300
C41: MiNi2-500
C42: MiNi4-500
A47: Model | B47: Material & Finish | C47: Thickness | D47: Protection | E47: Dimensions L X W X T | F47: Maximum working Pr. | G47: Test pressure | H47: Maximum exposure temp. | I47: Minimum running temp. | J47: Qty | K47: Absorbed power (Average/Max) | L47: Thermal power (Average/Max) | M47: Electrical support power | N47: Compressor Type | O47: Compressor Noise Level | P47: Circulation Pump | Q47: Net Weight | R47: Cabinet | S47: Dimension | T47: Cooling Fluid * | U47: Piping Material | V47: Line of liquid | W47: Line of aspiration | X47: Volume | Y47: Type of internal Tank | Z47: Hydraulic joints | AA47: Maximum pressure | AB47: Test pressure | AC47: Maximum water temp. | AD47: Water temperature | AE47: Power feed | AF47: Controller
A48: MiNi1-200 | B48: Powder coated Anodised aluminium Alloy panel | C48: 2mm aluminium for increased mechanical strength | D48: Corrosion resistant and adaptability to all weathers | E48: 2000 X 800 * 20 | F48: 10 | G48: 15 | H48: 100 | I48: 10 | J48: 1 | K48: 650 | L48: 3490 | M48: 1500 | N48: Rotary | O48: 45 | P48: Builtin Hot water circualtor Pump | R48: Stainless Steel / Galvanised Steek | S48: 500 X 450 X 375 | T48: R134a | U48: Copper (DHP ISO1337) | V48: 1/4” | W48: 3/8” | X48: 200 | Y48: MS with SPL EPOXY enamel Coated | Z48: 3/4” Male | 3/4” Male 1/2 Female | 3/4” Female | AA48: 7 | AB48: 10 | AC48: 60 | AD48: 55 | AE48: 230 Single Phase / 50 | AF48: Next Gen PCB controller
...
